#VRML_SIM R2019a utf8
WorldInfo {
}
Viewpoint {
  orientation 0.24258499478608286 -0.9374246837061674 -0.24977486399361323 4.618699657636912
  position 1.2589011557433913 0.9900397742064453 0.3434942858813007
}
TexturedBackground {
}
TexturedBackgroundLight {
}
Floor {
}
Solid {
  translation 0 0.25 0
  children [
    Shape {
      appearance PBRAppearance {
        baseColor 0.20392156862745098 0.396078431372549 0.6431372549019608
        roughness 1
        metalness 0
      }
      geometry Cylinder {
        height 0.5
        radius 0.05
      }
    }
    HingeJoint {
      jointParameters HingeJointParameters {
        axis 0 1 0
        anchor 0 0.255 0
        minStop -0.7854
        maxStop 0.785
        staticFriction 0.01
      }
      endPoint Solid {
        translation 0 0.255 0
        children [
          Shape {
            appearance PBRAppearance {
              baseColor 0.8 0 0
              roughness 1
              metalness 0
            }
            geometry Box {
              size 0.8 0.01 0.1
            }
          }
        ]
        physics Physics {
        }
      }
    }
    HingeJoint {
      jointParameters HingeJointParameters {
        axis 0 1 0
      }
      endPoint Solid {
        translation 0 0 0.055
        children [
          Shape {
            appearance PBRAppearance {
              baseColor 0.8 0 0
              roughness 1
              metalness 0
            }
            geometry Box {
              size 0.1 0.03 0.01
            }
          }
        ]
        name "solid(1)"
        physics Physics {
        }
      }
    }
  ]
}
